Workbook

Sheet Read me
A1: 2027 Capacity Exercise
A2: Risk Group — what to do, in the order to do it
A4: What to do
A5: 1. My structure | B5: Your group as it stands today, down to section level. Collapse and expand with the +/- buttons in the left margin. Nothing to fill in — read it and check it looks right.
A6: 2. Current capacity | B6: For each unit: what is approved, filled and vacant today, what drives its workload, and how much of that work one person gets through. This is what your ask will be argued against, so it is worth getting right.
A7: 3. Attrition & pipeline | B7: Who you already know is leaving, and what is already in recruitment. Confirm each 2026 vacancy you still need — anything you do not confirm will lapse.
A8: 4. Structure changes | B8: New units, moves, closures, merges and renames. Give a new unit a temporary ID here and you can then ask for positions into it on the next sheet.
A9: 5. Capacity asks | B9: One row per position you want. The cost is worked out for you as you type. Every row needs a driver, because that is what decides the order things get funded in.
A10: 6. My position | B10: Where your ask lands against your cost envelope, your headcount envelope and your Saudization target. Read this before you submit, not after.
A11: 7. Check & submit | B11: Everything still missing or invalid, listed row by row. When it is clear, set the state to Submitted and return the file.
A13: How to read this workbook
A14: Type here | B14: Yellow fill, blue text — the cells you fill in.
A15: Calculated | B15: Black — worked out by the sheet. Do not overwrite.
A16: From another sheet | B16: Green — pulled from elsewhere in this file.
A18: Two things worth knowing
A19: The cost shown to you is a loaded cost — basic, housing, transport, employer GOSI and target bonus — in SAR thousands. It is the same rate table the centre will price your ask with, so there are no surprises on the way back.
A20: A position asked for in Q1 costs a full year; one asked for in Q4 costs a quarter of a year. Moving a start date is the cheapest concession you can offer, and it is usually the first thing you will be asked for.

Sheet 1. My structure
A1: My structure
A2: Risk Group as it stands in 2026. Use the +/- buttons on the left to collapse and expand. 2027 fills in from your asks.
A4: Level | B4: Unit | C4: 2026 approved | D4: Filled | E4: Vacant | F4: 2027 asked | G4: 2027 total | H4: Change
A5: Group | B5: Risk Group | C5: 325 | D5: 290 | E5: 35 | F5: =SUMIFS('5. Capacity asks'!$H$6:$H$305,'5. Capacity asks'!$B$6:$B$305,$B5) -> 0 | G5: =$C5+$F5 -> 325 | H5: =$F5 -> 0
A6: Division | B6: Credit Risk Division | C6: 104 | D6: 94 | E6: 10 | F6: =SUMIFS('5. Capacity asks'!$H$6:$H$305,'5. Capacity asks'!$B$6:$B$305,$B6) -> 0 | G6: =$C6+$F6 -> 104 | H6: =$F6 -> 0
A7: Department | B7: Corporate Credit Risk | C7: 31 | D7: 30 | E7: 1 | F7: =SUMIFS('5. Capacity asks'!$H$6:$H$305,'5. Capacity asks'!$B$6:$B$305,$B7) -> 0 | G7: =$C7+$F7 -> 31 | H7: =$F7 -> 0
A8: Unit | B8: Corporate Credit Risk Unit 1 | C8: 17 | D8: 17 | E8: 0 | F8: =SUMIFS('5. Capacity asks'!$H$6:$H$305,'5. Capacity asks'!$B$6:$B$305,$B8) -> 0 | G8: =$C8+$F8 -> 17 | H8: =$F8 -> 0
A9: Sub-unit | B9: Corporate Credit Risk Unit 1 - Team A | C9: 10 | D9: 10 | E9: 0 | F9: =SUMIFS('5. Capacity asks'!$H$6:$H$305,'5. Capacity asks'!$B$6:$B$305,$B9) -> 0 | G9: =$C9+$F9 -> 10 | H9: =$F9 -> 0
A10: Sub-unit | B10: Corporate Credit Risk Unit 1 - Team B | C10: 6 | D10: 6 | E10: 0 | F10: =SUMIFS('5. Capacity asks'!$H$6:$H$305,'5. Capacity asks'!$B$6:$B$305,$B10) -> 0 | G10: =$C10+$F10 -> 6 | H10: =$F10 -> 0
A11: Unit | B11: Corporate Credit Risk Unit 2 | C11: 13 | D11: 12 | E11: 1 | F11: =SUMIFS('5. Capacity asks'!$H$6:$H$305,'5. Capacity asks'!$B$6:$B$305,$B11) -> 0 | G11: =$C11+$F11 -> 13 | H11: =$F11 -> 0
A12: Sub-unit | B12: Corporate Credit Risk Unit 2 - Team A | C12: 6 | D12: 5 | E12: 1 | F12: =SUMIFS('5. Capacity asks'!$H$6:$H$305,'5. Capacity asks'!$B$6:$B$305,$B12) -> 0 | G12: =$C12+$F12 -> 6 | H12: =$F12 -> 0
A13: Sub-unit | B13: Corporate Credit Risk Unit 2 - Team B | C13: 6 | D13: 6 | E13: 0 | F13: =SUMIFS('5. Capacity asks'!$H$6:$H$305,'5. Capacity asks'!$B$6:$B$305,$B13) -> 0 | G13: =$C13+$F13 -> 6 | H13: =$F13 -> 0
A14: Department | B14: Credit Administration | C14: 40 | D14: 32 | E14: 8 | F14: =SUMIFS('5. Capacity asks'!$H$6:$H$305,'5. Capacity asks'!$B$6:$B$305,$B14) -> 0 | G14: =$C14+$F14 -> 40 | H14: =$F14 -> 0
A15: Unit | B15: Credit Administration Unit 1 | C15: 20 | D15: 16 | E15: 4 | F15: =SUMIFS('5. Capacity asks'!$H$6:$H$305,'5. Capacity asks'!$B$6:$B$305,$B15) -> 0 | G15: =$C15+$F15 -> 20 | H15: =$F15 -> 0
A16: Sub-unit | B16: Credit Administration Unit 1 - Team A | C16: 10 | D16: 9 | E16: 1 | F16: =SUMIFS('5. Capacity asks'!$H$6:$H$305,'5. Capacity asks'!$B$6:$B$305,$B16) -> 0 | G16: =$C16+$F16 -> 10 | H16: =$F16 -> 0
... A72: Sub-unit | B72: Risk Modelling Unit 2 - Team B | C72: 9 | D72: 8 | E72: 1 | F72: =SUMIFS('5. Capacity asks'!$H$6:$H$305,'5. Capacity asks'!$B$6:$B$305,$B72) -> 0 | G72: =$C72+$F72 -> 9 | H72: =$F72 -> 0

Sheet 2. Current capacity
A1: Current capacity
A2: What each unit has today, what drives its work, and how much of that work one person gets through. The yellow cells are yours.
A4: Unit | B4: Approved | C4: Filled | D4: Vacant | E4: Workload driver | F4: 2026 volume | G4: 2027 expected volume | H4: Volume growth | I4: FTE on this work | J4: Output per FTE (2026) | K4: Productivity uplift | L4: 2027 FTE required | M4: Gap vs filled | N4: Overtime / insourced cover | O4: How stretched (1-5)
A5: Corporate Credit Risk | B5: 31 | C5: 30 | D5: 1 | H5: =IFERROR($G5/$F5-1,"") | J5: =IFERROR($F5/$I5,"") | L5: =IFERROR($G5/($J5*(1+IF($K5="",ProductivityDefault,$K5))),"") | M5: =IFERROR($L5-$C5,"")
A6: Corporate Credit Risk Unit 1 | B6: 17 | C6: 17 | D6: 0 | H6: =IFERROR($G6/$F6-1,"") | J6: =IFERROR($F6/$I6,"") | L6: =IFERROR($G6/($J6*(1+IF($K6="",ProductivityDefault,$K6))),"") | M6: =IFERROR($L6-$C6,"")
A7: Corporate Credit Risk Unit 2 | B7: 13 | C7: 12 | D7: 1 | H7: =IFERROR($G7/$F7-1,"") | J7: =IFERROR($F7/$I7,"") | L7: =IFERROR($G7/($J7*(1+IF($K7="",ProductivityDefault,$K7))),"") | M7: =IFERROR($L7-$C7,"")
A8: Credit Administration | B8: 40 | C8: 32 | D8: 8 | H8: =IFERROR($G8/$F8-1,"") | J8: =IFERROR($F8/$I8,"") | L8: =IFERROR($G8/($J8*(1+IF($K8="",ProductivityDefault,$K8))),"") | M8: =IFERROR($L8-$C8,"")
A9: Credit Administration Unit 1 | B9: 20 | C9: 16 | D9: 4 | H9: =IFERROR($G9/$F9-1,"") | J9: =IFERROR($F9/$I9,"") | L9: =IFERROR($G9/($J9*(1+IF($K9="",ProductivityDefault,$K9))),"") | M9: =IFERROR($L9-$C9,"")
A10: Credit Administration Unit 2 | B10: 19 | C10: 15 | D10: 4 | H10: =IFERROR($G10/$F10-1,"") | J10: =IFERROR($F10/$I10,"") | L10: =IFERROR($G10/($J10*(1+IF($K10="",ProductivityDefault,$K10))),"") | M10: =IFERROR($L10-$C10,"")
A11: Retail Credit Risk | B11: 32 | C11: 31 | D11: 1 | H11: =IFERROR($G11/$F11-1,"") | J11: =IFERROR($F11/$I11,"") | L11: =IFERROR($G11/($J11*(1+IF($K11="",ProductivityDefault,$K11))),"") | M11: =IFERROR($L11-$C11,"")
A12: Retail Credit Risk Unit 1 | B12: 17 | C12: 16 | D12: 1 | H12: =IFERROR($G12/$F12-1,"") | J12: =IFERROR($F12/$I12,"") | L12: =IFERROR($G12/($J12*(1+IF($K12="",ProductivityDefault,$K12))),"") | M12: =IFERROR($L12-$C12,"")
A13: Retail Credit Risk Unit 2 | B13: 14 | C13: 14 | D13: 0 | H13: =IFERROR($G13/$F13-1,"") | J13: =IFERROR($F13/$I13,"") | L13: =IFERROR($G13/($J13*(1+IF($K13="",ProductivityDefault,$K13))),"") | M13: =IFERROR($L13-$C13,"")
A14: Liquidity Risk | B14: 34 | C14: 28 | D14: 6 | H14: =IFERROR($G14/$F14-1,"") | J14: =IFERROR($F14/$I14,"") | L14: =IFERROR($G14/($J14*(1+IF($K14="",ProductivityDefault,$K14))),"") | M14: =IFERROR($L14-$C14,"")
A15: Liquidity Risk Unit 1 | B15: 17 | C15: 14 | D15: 3 | H15: =IFERROR($G15/$F15-1,"") | J15: =IFERROR($F15/$I15,"") | L15: =IFERROR($G15/($J15*(1+IF($K15="",ProductivityDefault,$K15))),"") | M15: =IFERROR($L15-$C15,"")
A16: Liquidity Risk Unit 2 | B16: 16 | C16: 13 | D16: 3 | H16: =IFERROR($G16/$F16-1,"") | J16: =IFERROR($F16/$I16,"") | L16: =IFERROR($G16/($J16*(1+IF($K16="",ProductivityDefault,$K16))),"") | M16: =IFERROR($L16-$C16,"")
... A31: Risk Modelling Unit 2 | B31: 20 | C31: 19 | D31: 1 | H31: =IFERROR($G31/$F31-1,"") | J31: =IFERROR($F31/$I31,"") | L31: =IFERROR($G31/($J31*(1+IF($K31="",ProductivityDefault,$K31))),"") | M31: =IFERROR($L31-$C31,"")
A33: Output per FTE is worked out from what you type: volume divided by the FTE doing it. Required FTE for 2027 is next year's volume divided by that same rate, improved by the productivity uplift. Leave the uplift blank to use the bank default.

Sheet 3. Attrition & pipeline
A1: Attrition & pipeline
A2: Who you already know is going, what rate applies to everyone else, and which 2026 vacancies you still need.
A4: Rate
A5: Bank default attrition rate | B5: =AttritionDefault -> 0.09
A6: This group's rate (leave blank to use the default) | C6: Blue cells are yours.
A7: Filled headcount today | B7: 290 | C7: From the 2026 establishment.
A8: Leavers implied by the rate | B8: =ROUND($B$7*IF($B$6="",AttritionDefault,$B$6),0) -> 26
A9: Of which already named below | B9: =COUNTA($B$14:$B$73) -> 17
A10: Further leavers to assume | B10: =MAX(0,$B$8-$B$9) -> 9 | C10: What the rate expects on top of the names you know.
A12: Named leavers and retirements | D12: Pre-filled from assignment end dates already in the HR system.
A13: Unit | B13: Job title | C13: Grade | D13: Leaving date | E13: Quarter | F13: Reason | G13: Backfill needed?
A14: IFRS 9 & Provisioning Unit 2 - Team B | B14: Associate IFRS 9 & Provisioning | C14: G10 | D14: 2026-09-13 | E14: Q3 | F14: Resignation / assignment end | G14: Yes
A15: Operational Risk Unit 1 - Team A | B15: Analyst Operational Risk | C15: G10 | D15: 2026-09-16 | E15: Q3 | F15: Resignation / assignment end | G15: Yes
A16: Retail Credit Risk Unit 2 | B16: Manager Retail Credit Risk | C16: G13 | D16: 2026-09-23 | E16: Q3 | F16: Resignation / assignment end | G16: Yes
A17: Risk Modelling Unit 2 - Team B | B17: Associate Risk Modelling | C17: G11 | D17: 2026-10-12 | E17: Q4 | F17: Resignation / assignment end | G17: Yes
A18: Credit Administration Unit 2 | B18: Manager Credit Administration | C18: G13 | D18: 2026-10-31 | E18: Q4 | F18: Resignation / assignment end | G18: Yes
A19: Business Continuity Unit 1 - Team A | B19: Analyst Business Continuity | C19: G10 | D19: 2026-11-05 | E19: Q4 | F19: Resignation / assignment end | G19: Yes
A20: Business Continuity Unit 1 - Team B | B20: Senior Officer Business Continuity | C20: G10 | D20: 2026-11-08 | E20: Q4 | F20: Resignation / assignment end | G20: Yes
A21: Business Continuity Unit 1 - Team A | B21: Associate Business Continuity | C21: G11 | D21: 2026-11-12 | E21: Q4 | F21: Resignation / assignment end | G21: Yes
A22: Liquidity Risk Unit 2 - Team A | B22: Associate Liquidity Risk | C22: G9 | D22: 2026-11-15 | E22: Q4 | F22: Resignation / assignment end | G22: Yes
A23: Business Continuity Unit 1 - Team A | B23: Officer Business Continuity | C23: G9 | D23: 2026-11-16 | E23: Q4 | F23: Resignation / assignment end | G23: Yes
A24: Market Risk Unit 1 - Team A | B24: Analyst Market Risk | C24: G9 | D24: 2026-11-18 | E24: Q4 | F24: Resignation / assignment end | G24: Yes
... A30: Risk Modelling Unit 1 - Team A | B30: Analyst Risk Modelling | C30: G11 | D30: 2027-01-14 | E30: Q1 | F30: Resignation / assignment end | G30: Yes
A75: 2026 vacancies — confirm each one you still need | D75: Anything not confirmed lapses and will not carry into 2027.
A76: Unit | B76: Job title | C76: Grade | D76: Last held by | E76: Still needed? | F76: If not, why
A77: Business Continuity Unit 1 - Team A | B77: Senior Analyst Business Continuity | C77: G10 | D77: Jana Saleh
A78: Business Continuity Unit 1 - Team B | B78: Officer Business Continuity | C78: G9
A79: Business Continuity Unit 2 - Team A | B79: Specialist Business Continuity | C79: G11 | D79: Bilal Saleh
A80: Business Continuity Unit 2 - Team B | B80: Senior Officer Business Continuity | C80: G11 | D80: Dana Bakr
A81: Corporate Credit Risk Unit 2 - Team A | B81: Associate Corporate Credit Risk | C81: G10
A82: Credit Administration Unit 1 - Team A | B82: Associate Credit Administration | C82: G9 | D82: خالد الدوسري
A83: Credit Administration Unit 1 - Team B | B83: Associate Credit Administration | C83: G11 | D83: Noor Mansour
A84: Credit Administration Unit 1 - Team B | B84: Officer Credit Administration | C84: G10
A85: Credit Administration Unit 1 - Team B | B85: Senior Analyst Credit Administration | C85: G9 | D85: Noor Karim
A86: Credit Administration Unit 2 - Team A | B86: Analyst Credit Administration | C86: G9 | D86: Maya Qureshi
A87: Credit Administration Unit 2 - Team A | B87: Senior Analyst Credit Administration | C87: G10 | D87: Adel Darwish
A88: Credit Administration Unit 2 - Team A | B88: Team Lead Credit Administration | C88: G12 | D88: عبدالله الزهراني
A89: Credit Administration Unit 2 - Team B | B89: Specialist Credit Administration | C89: G11
A90: IFRS 9 & Provisioning Unit 1 | B90: Manager IFRS 9 & Provisioning | C90: G13 | D90: Mona Aziz
A91: IFRS 9 & Provisioning Unit 1 - Team B | B91: Specialist IFRS 9 & Provisioning | C91: G11
...

Sheet 4. Structure changes
A1: Structure changes
A2: What you want the 2027 structure to look like where it differs from today. Give a new unit an ID and you can ask for positions into it.
A4: Change ID | B4: Action | C4: Unit name | D4: Level | E4: Parent unit | F4: Function type | G4: Mandate / why | H4: People affected | I4: Effective from | J4: Ready to use
A5: NEW-01 | J5: =IF(AND($B5<>"",$C5<>""),$A5,"")
A6: NEW-02 | J6: =IF(AND($B6<>"",$C6<>""),$A6,"")
A7: NEW-03 | J7: =IF(AND($B7<>"",$C7<>""),$A7,"")
A8: NEW-04 | J8: =IF(AND($B8<>"",$C8<>""),$A8,"")
A9: NEW-05 | J9: =IF(AND($B9<>"",$C9<>""),$A9,"")
A10: NEW-06 | J10: =IF(AND($B10<>"",$C10<>""),$A10,"")
A11: NEW-07 | J11: =IF(AND($B11<>"",$C11<>""),$A11,"")
A12: NEW-08 | J12: =IF(AND($B12<>"",$C12<>""),$A12,"")
A13: NEW-09 | J13: =IF(AND($B13<>"",$C13<>""),$A13,"")
A14: NEW-10 | J14: =IF(AND($B14<>"",$C14<>""),$A14,"")
A15: NEW-11 | J15: =IF(AND($B15<>"",$C15<>""),$A15,"")
A16: NEW-12 | J16: =IF(AND($B16<>"",$C16<>""),$A16,"")
... A44: NEW-40 | J44: =IF(AND($B44<>"",$C44<>""),$A44,"")
A46: A new unit needs a name, a level and a parent before a position can be asked into it. Closures and merges need the people affected, because that is what funds the growth elsewhere.

Sheet 5. Capacity asks
A1: Capacity asks
A2: One row per position you want in 2027. Cost is worked out as you type.
A5: Ref | B5: Unit (or new unit ID) | C5: Job title | D5: Grade | E5: Workforce type | F5: Saudi basis | G5: Nature | H5: FTE | I5: Start quarter | J5: Driver | K5: Category | L5: Rank | M5: Alternatives considered | N5: Note | O5: Loaded cost (full year) | P5: One-off | Q5: 2027 in-year cost | R5: Run-rate | S5: What's missing | T5: Issue no.
A6: 1 | K6: =IF($J6="","",IFERROR(INDEX(DriverCategory,MATCH($J6,DriverList,0)),"?")) | L6: =IF($J6="","",IFERROR(INDEX(DriverRank,MATCH($J6,DriverList,0)),99)) | O6: =IF($D6="","",INDEX(GradeBasic,MATCH($D6,GradeList,0))+INDEX(GradeHousing,MATCH($D6,GradeList,0))+INDEX(GradeTransport,MATCH($D6,GradeList,0))+INDEX(GradeBasic,MATCH($D6,GradeList,0))*INDEX(GradeBonus,MATCH($D6,GradeList,0))+(INDEX(GradeBasic,MATCH($D6,GradeList,0))+INDEX(GradeHousing,MATCH($D6,GradeList,0)))*IF($F6="Saudi",GosiSaudi,GosiOther)) | P6: =IF($D6="","",IF(INDEX(GradeRank,MATCH($D6,GradeList,0))>=INDEX(GradeRank,MATCH("G14",GradeList,0)),OneOffSenior,OneOffJunior)) | Q6: =IF(OR($D6="",$I6="",$H6=""),"",$O6*$H6*(5-MATCH($I6,{"Q1";"Q2";"Q3";"Q4"},0))/4+$P6*$H6) | R6: =IF($O6="","",$O6*$H6) | S6: =IF(COUNTA($B6:$J6)+COUNTA($M6:$N6)=0,"",MID(IF($B6="",", unit","")&IF($C6="",", job title","")&IF($D6="",", grade","")&IF($E6="",", workforce type","")&IF($F6="",", Saudi basis","")&IF($G6="",", nature","")&IF(N($H6)<=0,", FTE","")&IF($I6="",", start quarter","")&IF($J6="",", driver","")&IF($M6="",", alternatives",""),3,300)) | T6: =IF($S6="","",COUNTIF($S$6:$S6,"?*"))
A7: 2 | K7: =IF($J7="","",IFERROR(INDEX(DriverCategory,MATCH($J7,DriverList,0)),"?")) | L7: =IF($J7="","",IFERROR(INDEX(DriverRank,MATCH($J7,DriverList,0)),99)) | O7: =IF($D7="","",INDEX(GradeBasic,MATCH($D7,GradeList,0))+INDEX(GradeHousing,MATCH($D7,GradeList,0))+INDEX(GradeTransport,MATCH($D7,GradeList,0))+INDEX(GradeBasic,MATCH($D7,GradeList,0))*INDEX(GradeBonus,MATCH($D7,GradeList,0))+(INDEX(GradeBasic,MATCH($D7,GradeList,0))+INDEX(GradeHousing,MATCH($D7,GradeList,0)))*IF($F7="Saudi",GosiSaudi,GosiOther)) | P7: =IF($D7="","",IF(INDEX(GradeRank,MATCH($D7,GradeList,0))>=INDEX(GradeRank,MATCH("G14",GradeList,0)),OneOffSenior,OneOffJunior)) | Q7: =IF(OR($D7="",$I7="",$H7=""),"",$O7*$H7*(5-MATCH($I7,{"Q1";"Q2";"Q3";"Q4"},0))/4+$P7*$H7) | R7: =IF($O7="","",$O7*$H7) | S7: =IF(COUNTA($B7:$J7)+COUNTA($M7:$N7)=0,"",MID(IF($B7="",", unit","")&IF($C7="",", job title","")&IF($D7="",", grade","")&IF($E7="",", workforce type","")&IF($F7="",", Saudi basis","")&IF($G7="",", nature","")&IF(N($H7)<=0,", FTE","")&IF($I7="",", start quarter","")&IF($J7="",", driver","")&IF($M7="",", alternatives",""),3,300)) | T7: =IF($S7="","",COUNTIF($S$6:$S7,"?*"))
A8: 3 | K8: =IF($J8="","",IFERROR(INDEX(DriverCategory,MATCH($J8,DriverList,0)),"?")) | L8: =IF($J8="","",IFERROR(INDEX(DriverRank,MATCH($J8,DriverList,0)),99)) | O8: =IF($D8="","",INDEX(GradeBasic,MATCH($D8,GradeList,0))+INDEX(GradeHousing,MATCH($D8,GradeList,0))+INDEX(GradeTransport,MATCH($D8,GradeList,0))+INDEX(GradeBasic,MATCH($D8,GradeList,0))*INDEX(GradeBonus,MATCH($D8,GradeList,0))+(INDEX(GradeBasic,MATCH($D8,GradeList,0))+INDEX(GradeHousing,MATCH($D8,GradeList,0)))*IF($F8="Saudi",GosiSaudi,GosiOther)) | P8: =IF($D8="","",IF(INDEX(GradeRank,MATCH($D8,GradeList,0))>=INDEX(GradeRank,MATCH("G14",GradeList,0)),OneOffSenior,OneOffJunior)) | Q8: =IF(OR($D8="",$I8="",$H8=""),"",$O8*$H8*(5-MATCH($I8,{"Q1";"Q2";"Q3";"Q4"},0))/4+$P8*$H8) | R8: =IF($O8="","",$O8*$H8) | S8: =IF(COUNTA($B8:$J8)+COUNTA($M8:$N8)=0,"",MID(IF($B8="",", unit","")&IF($C8="",", job title","")&IF($D8="",", grade","")&IF($E8="",", workforce type","")&IF($F8="",", Saudi basis","")&IF($G8="",", nature","")&IF(N($H8)<=0,", FTE","")&IF($I8="",", start quarter","")&IF($J8="",", driver","")&IF($M8="",", alternatives",""),3,300)) | T8: =IF($S8="","",COUNTIF($S$6:$S8,"?*"))
A9: 4 | K9: =IF($J9="","",IFERROR(INDEX(DriverCategory,MATCH($J9,DriverList,0)),"?")) | L9: =IF($J9="","",IFERROR(INDEX(DriverRank,MATCH($J9,DriverList,0)),99)) | O9: =IF($D9="","",INDEX(GradeBasic,MATCH($D9,GradeList,0))+INDEX(GradeHousing,MATCH($D9,GradeList,0))+INDEX(GradeTransport,MATCH($D9,GradeList,0))+INDEX(GradeBasic,MATCH($D9,GradeList,0))*INDEX(GradeBonus,MATCH($D9,GradeList,0))+(INDEX(GradeBasic,MATCH($D9,GradeList,0))+INDEX(GradeHousing,MATCH($D9,GradeList,0)))*IF($F9="Saudi",GosiSaudi,GosiOther)) | P9: =IF($D9="","",IF(INDEX(GradeRank,MATCH($D9,GradeList,0))>=INDEX(GradeRank,MATCH("G14",GradeList,0)),OneOffSenior,OneOffJunior)) | Q9: =IF(OR($D9="",$I9="",$H9=""),"",$O9*$H9*(5-MATCH($I9,{"Q1";"Q2";"Q3";"Q4"},0))/4+$P9*$H9) | R9: =IF($O9="","",$O9*$H9) | S9: =IF(COUNTA($B9:$J9)+COUNTA($M9:$N9)=0,"",MID(IF($B9="",", unit","")&IF($C9="",", job title","")&IF($D9="",", grade","")&IF($E9="",", workforce type","")&IF($F9="",", Saudi basis","")&IF($G9="",", nature","")&IF(N($H9)<=0,", FTE","")&IF($I9="",", start quarter","")&IF($J9="",", driver","")&IF($M9="",", alternatives",""),3,300)) | T9: =IF($S9="","",COUNTIF($S$6:$S9,"?*"))
A10: 5 | K10: =IF($J10="","",IFERROR(INDEX(DriverCategory,MATCH($J10,DriverList,0)),"?")) | L10: =IF($J10="","",IFERROR(INDEX(DriverRank,MATCH($J10,DriverList,0)),99)) | O10: =IF($D10="","",INDEX(GradeBasic,MATCH($D10,GradeList,0))+INDEX(GradeHousing,MATCH($D10,GradeList,0))+INDEX(GradeTransport,MATCH($D10,GradeList,0))+INDEX(GradeBasic,MATCH($D10,GradeList,0))*INDEX(GradeBonus,MATCH($D10,GradeList,0))+(INDEX(GradeBasic,MATCH($D10,GradeList,0))+INDEX(GradeHousing,MATCH($D10,GradeList,0)))*IF($F10="Saudi",GosiSaudi,GosiOther)) | P10: =IF($D10="","",IF(INDEX(GradeRank,MATCH($D10,GradeList,0))>=INDEX(GradeRank,MATCH("G14",GradeList,0)),OneOffSenior,OneOffJunior)) | Q10: =IF(OR($D10="",$I10="",$H10=""),"",$O10*$H10*(5-MATCH($I10,{"Q1";"Q2";"Q3";"Q4"},0))/4+$P10*$H10) | R10: =IF($O10="","",$O10*$H10) | S10: =IF(COUNTA($B10:$J10)+COUNTA($M10:$N10)=0,"",MID(IF($B10="",", unit","")&IF($C10="",", job title","")&IF($D10="",", grade","")&IF($E10="",", workforce type","")&IF($F10="",", Saudi basis","")&IF($G10="",", nature","")&IF(N($H10)<=0,", FTE","")&IF($I10="",", start quarter","")&IF($J10="",", driver","")&IF($M10="",", alternatives",""),3,300)) | T10: =IF($S10="","",COUNTIF($S$6:$S10,"?*"))
A11: 6 | K11: =IF($J11="","",IFERROR(INDEX(DriverCategory,MATCH($J11,DriverList,0)),"?")) | L11: =IF($J11="","",IFERROR(INDEX(DriverRank,MATCH($J11,DriverList,0)),99)) | O11: =IF($D11="","",INDEX(GradeBasic,MATCH($D11,GradeList,0))+INDEX(GradeHousing,MATCH($D11,GradeList,0))+INDEX(GradeTransport,MATCH($D11,GradeList,0))+INDEX(GradeBasic,MATCH($D11,GradeList,0))*INDEX(GradeBonus,MATCH($D11,GradeList,0))+(INDEX(GradeBasic,MATCH($D11,GradeList,0))+INDEX(GradeHousing,MATCH($D11,GradeList,0)))*IF($F11="Saudi",GosiSaudi,GosiOther)) | P11: =IF($D11="","",IF(INDEX(GradeRank,MATCH($D11,GradeList,0))>=INDEX(GradeRank,MATCH("G14",GradeList,0)),OneOffSenior,OneOffJunior)) | Q11: =IF(OR($D11="",$I11="",$H11=""),"",$O11*$H11*(5-MATCH($I11,{"Q1";"Q2";"Q3";"Q4"},0))/4+$P11*$H11) | R11: =IF($O11="","",$O11*$H11) | S11: =IF(COUNTA($B11:$J11)+COUNTA($M11:$N11)=0,"",MID(IF($B11="",", unit","")&IF($C11="",", job title","")&IF($D11="",", grade","")&IF($E11="",", workforce type","")&IF($F11="",", Saudi basis","")&IF($G11="",", nature","")&IF(N($H11)<=0,", FTE","")&IF($I11="",", start quarter","")&IF($J11="",", driver","")&IF($M11="",", alternatives",""),3,300)) | T11: =IF($S11="","",COUNTIF($S$6:$S11,"?*"))
A12: 7 | K12: =IF($J12="","",IFERROR(INDEX(DriverCategory,MATCH($J12,DriverList,0)),"?")) | L12: =IF($J12="","",IFERROR(INDEX(DriverRank,MATCH($J12,DriverList,0)),99)) | O12: =IF($D12="","",INDEX(GradeBasic,MATCH($D12,GradeList,0))+INDEX(GradeHousing,MATCH($D12,GradeList,0))+INDEX(GradeTransport,MATCH($D12,GradeList,0))+INDEX(GradeBasic,MATCH($D12,GradeList,0))*INDEX(GradeBonus,MATCH($D12,GradeList,0))+(INDEX(GradeBasic,MATCH($D12,GradeList,0))+INDEX(GradeHousing,MATCH($D12,GradeList,0)))*IF($F12="Saudi",GosiSaudi,GosiOther)) | P12: =IF($D12="","",IF(INDEX(GradeRank,MATCH($D12,GradeList,0))>=INDEX(GradeRank,MATCH("G14",GradeList,0)),OneOffSenior,OneOffJunior)) | Q12: =IF(OR($D12="",$I12="",$H12=""),"",$O12*$H12*(5-MATCH($I12,{"Q1";"Q2";"Q3";"Q4"},0))/4+$P12*$H12) | R12: =IF($O12="","",$O12*$H12) | S12: =IF(COUNTA($B12:$J12)+COUNTA($M12:$N12)=0,"",MID(IF($B12="",", unit","")&IF($C12="",", job title","")&IF($D12="",", grade","")&IF($E12="",", workforce type","")&IF($F12="",", Saudi basis","")&IF($G12="",", nature","")&IF(N($H12)<=0,", FTE","")&IF($I12="",", start quarter","")&IF($J12="",", driver","")&IF($M12="",", alternatives",""),3,300)) | T12: =IF($S12="","",COUNTIF($S$6:$S12,"?*"))
A13: 8 | K13: =IF($J13="","",IFERROR(INDEX(DriverCategory,MATCH($J13,DriverList,0)),"?")) | L13: =IF($J13="","",IFERROR(INDEX(DriverRank,MATCH($J13,DriverList,0)),99)) | O13: =IF($D13="","",INDEX(GradeBasic,MATCH($D13,GradeList,0))+INDEX(GradeHousing,MATCH($D13,GradeList,0))+INDEX(GradeTransport,MATCH($D13,GradeList,0))+INDEX(GradeBasic,MATCH($D13,GradeList,0))*INDEX(GradeBonus,MATCH($D13,GradeList,0))+(INDEX(GradeBasic,MATCH($D13,GradeList,0))+INDEX(GradeHousing,MATCH($D13,GradeList,0)))*IF($F13="Saudi",GosiSaudi,GosiOther)) | P13: =IF($D13="","",IF(INDEX(GradeRank,MATCH($D13,GradeList,0))>=INDEX(GradeRank,MATCH("G14",GradeList,0)),OneOffSenior,OneOffJunior)) | Q13: =IF(OR($D13="",$I13="",$H13=""),"",$O13*$H13*(5-MATCH($I13,{"Q1";"Q2";"Q3";"Q4"},0))/4+$P13*$H13) | R13: =IF($O13="","",$O13*$H13) | S13: =IF(COUNTA($B13:$J13)+COUNTA($M13:$N13)=0,"",MID(IF($B13="",", unit","")&IF($C13="",", job title","")&IF($D13="",", grade","")&IF($E13="",", workforce type","")&IF($F13="",", Saudi basis","")&IF($G13="",", nature","")&IF(N($H13)<=0,", FTE","")&IF($I13="",", start quarter","")&IF($J13="",", driver","")&IF($M13="",", alternatives",""),3,300)) | T13: =IF($S13="","",COUNTIF($S$6:$S13,"?*"))
A14: 9 | K14: =IF($J14="","",IFERROR(INDEX(DriverCategory,MATCH($J14,DriverList,0)),"?")) | L14: =IF($J14="","",IFERROR(INDEX(DriverRank,MATCH($J14,DriverList,0)),99)) | O14: =IF($D14="","",INDEX(GradeBasic,MATCH($D14,GradeList,0))+INDEX(GradeHousing,MATCH($D14,GradeList,0))+INDEX(GradeTransport,MATCH($D14,GradeList,0))+INDEX(GradeBasic,MATCH($D14,GradeList,0))*INDEX(GradeBonus,MATCH($D14,GradeList,0))+(INDEX(GradeBasic,MATCH($D14,GradeList,0))+INDEX(GradeHousing,MATCH($D14,GradeList,0)))*IF($F14="Saudi",GosiSaudi,GosiOther)) | P14: =IF($D14="","",IF(INDEX(GradeRank,MATCH($D14,GradeList,0))>=INDEX(GradeRank,MATCH("G14",GradeList,0)),OneOffSenior,OneOffJunior)) | Q14: =IF(OR($D14="",$I14="",$H14=""),"",$O14*$H14*(5-MATCH($I14,{"Q1";"Q2";"Q3";"Q4"},0))/4+$P14*$H14) | R14: =IF($O14="","",$O14*$H14) | S14: =IF(COUNTA($B14:$J14)+COUNTA($M14:$N14)=0,"",MID(IF($B14="",", unit","")&IF($C14="",", job title","")&IF($D14="",", grade","")&IF($E14="",", workforce type","")&IF($F14="",", Saudi basis","")&IF($G14="",", nature","")&IF(N($H14)<=0,", FTE","")&IF($I14="",", start quarter","")&IF($J14="",", driver","")&IF($M14="",", alternatives",""),3,300)) | T14: =IF($S14="","",COUNTIF($S$6:$S14,"?*"))
A15: 10 | K15: =IF($J15="","",IFERROR(INDEX(DriverCategory,MATCH($J15,DriverList,0)),"?")) | L15: =IF($J15="","",IFERROR(INDEX(DriverRank,MATCH($J15,DriverList,0)),99)) | O15: =IF($D15="","",INDEX(GradeBasic,MATCH($D15,GradeList,0))+INDEX(GradeHousing,MATCH($D15,GradeList,0))+INDEX(GradeTransport,MATCH($D15,GradeList,0))+INDEX(GradeBasic,MATCH($D15,GradeList,0))*INDEX(GradeBonus,MATCH($D15,GradeList,0))+(INDEX(GradeBasic,MATCH($D15,GradeList,0))+INDEX(GradeHousing,MATCH($D15,GradeList,0)))*IF($F15="Saudi",GosiSaudi,GosiOther)) | P15: =IF($D15="","",IF(INDEX(GradeRank,MATCH($D15,GradeList,0))>=INDEX(GradeRank,MATCH("G14",GradeList,0)),OneOffSenior,OneOffJunior)) | Q15: =IF(OR($D15="",$I15="",$H15=""),"",$O15*$H15*(5-MATCH($I15,{"Q1";"Q2";"Q3";"Q4"},0))/4+$P15*$H15) | R15: =IF($O15="","",$O15*$H15) | S15: =IF(COUNTA($B15:$J15)+COUNTA($M15:$N15)=0,"",MID(IF($B15="",", unit","")&IF($C15="",", job title","")&IF($D15="",", grade","")&IF($E15="",", workforce type","")&IF($F15="",", Saudi basis","")&IF($G15="",", nature","")&IF(N($H15)<=0,", FTE","")&IF($I15="",", start quarter","")&IF($J15="",", driver","")&IF($M15="",", alternatives",""),3,300)) | T15: =IF($S15="","",COUNTIF($S$6:$S15,"?*"))
A16: 11 | K16: =IF($J16="","",IFERROR(INDEX(DriverCategory,MATCH($J16,DriverList,0)),"?")) | L16: =IF($J16="","",IFERROR(INDEX(DriverRank,MATCH($J16,DriverList,0)),99)) | O16: =IF($D16="","",INDEX(GradeBasic,MATCH($D16,GradeList,0))+INDEX(GradeHousing,MATCH($D16,GradeList,0))+INDEX(GradeTransport,MATCH($D16,GradeList,0))+INDEX(GradeBasic,MATCH($D16,GradeList,0))*INDEX(GradeBonus,MATCH($D16,GradeList,0))+(INDEX(GradeBasic,MATCH($D16,GradeList,0))+INDEX(GradeHousing,MATCH($D16,GradeList,0)))*IF($F16="Saudi",GosiSaudi,GosiOther)) | P16: =IF($D16="","",IF(INDEX(GradeRank,MATCH($D16,GradeList,0))>=INDEX(GradeRank,MATCH("G14",GradeList,0)),OneOffSenior,OneOffJunior)) | Q16: =IF(OR($D16="",$I16="",$H16=""),"",$O16*$H16*(5-MATCH($I16,{"Q1";"Q2";"Q3";"Q4"},0))/4+$P16*$H16) | R16: =IF($O16="","",$O16*$H16) | S16: =IF(COUNTA($B16:$J16)+COUNTA($M16:$N16)=0,"",MID(IF($B16="",", unit","")&IF($C16="",", job title","")&IF($D16="",", grade","")&IF($E16="",", workforce type","")&IF($F16="",", Saudi basis","")&IF($G16="",", nature","")&IF(N($H16)<=0,", FTE","")&IF($I16="",", start quarter","")&IF($J16="",", driver","")&IF($M16="",", alternatives",""),3,300)) | T16: =IF($S16="","",COUNTIF($S$6:$S16,"?*"))
A17: 12 | K17: =IF($J17="","",IFERROR(INDEX(DriverCategory,MATCH($J17,DriverList,0)),"?")) | L17: =IF($J17="","",IFERROR(INDEX(DriverRank,MATCH($J17,DriverList,0)),99)) | O17: =IF($D17="","",INDEX(GradeBasic,MATCH($D17,GradeList,0))+INDEX(GradeHousing,MATCH($D17,GradeList,0))+INDEX(GradeTransport,MATCH($D17,GradeList,0))+INDEX(GradeBasic,MATCH($D17,GradeList,0))*INDEX(GradeBonus,MATCH($D17,GradeList,0))+(INDEX(GradeBasic,MATCH($D17,GradeList,0))+INDEX(GradeHousing,MATCH($D17,GradeList,0)))*IF($F17="Saudi",GosiSaudi,GosiOther)) | P17: =IF($D17="","",IF(INDEX(GradeRank,MATCH($D17,GradeList,0))>=INDEX(GradeRank,MATCH("G14",GradeList,0)),OneOffSenior,OneOffJunior)) | Q17: =IF(OR($D17="",$I17="",$H17=""),"",$O17*$H17*(5-MATCH($I17,{"Q1";"Q2";"Q3";"Q4"},0))/4+$P17*$H17) | R17: =IF($O17="","",$O17*$H17) | S17: =IF(COUNTA($B17:$J17)+COUNTA($M17:$N17)=0,"",MID(IF($B17="",", unit","")&IF($C17="",", job title","")&IF($D17="",", grade","")&IF($E17="",", workforce type","")&IF($F17="",", Saudi basis","")&IF($G17="",", nature","")&IF(N($H17)<=0,", FTE","")&IF($I17="",", start quarter","")&IF($J17="",", driver","")&IF($M17="",", alternatives",""),3,300)) | T17: =IF($S17="","",COUNTIF($S$6:$S17,"?*"))
... A305: 300 | K305: =IF($J305="","",IFERROR(INDEX(DriverCategory,MATCH($J305,DriverList,0)),"?")) | L305: =IF($J305="","",IFERROR(INDEX(DriverRank,MATCH($J305,DriverList,0)),99)) | O305: =IF($D305="","",INDEX(GradeBasic,MATCH($D305,GradeList,0))+INDEX(GradeHousing,MATCH($D305,GradeList,0))+INDEX(GradeTransport,MATCH($D305,GradeList,0))+INDEX(GradeBasic,MATCH($D305,GradeList,0))*INDEX(GradeBonus,MATCH($D305,GradeList,0))+(INDEX(GradeBasic,MATCH($D305,GradeList,0))+INDEX(GradeHousing,MATCH($D305,GradeList,0)))*IF($F305="Saudi",GosiSaudi,GosiOther)) | P305: =IF($D305="","",IF(INDEX(GradeRank,MATCH($D305,GradeList,0))>=INDEX(GradeRank,MATCH("G14",GradeList,0)),OneOffSenior,OneOffJunior)) | Q305: =IF(OR($D305="",$I305="",$H305=""),"",$O305*$H305*(5-MATCH($I305,{"Q1";"Q2";"Q3";"Q4"},0))/4+$P305*$H305) | R305: =IF($O305="","",$O305*$H305) | S305: =IF(COUNTA($B305:$J305)+COUNTA($M305:$N305)=0,"",MID(IF($B305="",", unit","")&IF($C305="",", job title","")&IF($D305="",", grade","")&IF($E305="",", workforce type","")&IF($F305="",", Saudi basis","")&IF($G305="",", nature","")&IF(N($H305)<=0,", FTE","")&IF($I305="",", start quarter","")&IF($J305="",", driver","")&IF($M305="",", alternatives",""),3,300)) | T305: =IF($S305="","",COUNTIF($S$6:$S305,"?*"))

Sheet 6. My position
A1: My position
A2: Where your ask lands against your cost envelope, your headcount envelope and your Saudization target. Nothing here is typed in.
A4: 2026 baseline
A5: Filled headcount today | B5: 290
A6: Saudi nationals today | B6: 180
A7: Saudization today | B7: =IFERROR($B$6/$B$5,0) -> 0.62068966
A9: Your 2027 ask
A10: Positions asked for (FTE) | B10: =SUM('5. Capacity asks'!$H$6:$H$305) -> 0
A11: of which permanent | B11: =SUMIFS('5. Capacity asks'!$H$6:$H$305,'5. Capacity asks'!$E$6:$E$305,"Permanent") -> 0
A12: of which insourced | B12: =SUMIFS('5. Capacity asks'!$H$6:$H$305,'5. Capacity asks'!$E$6:$E$305,"Insourced") -> 0
A13: of which outsourced | B13: =SUMIFS('5. Capacity asks'!$H$6:$H$305,'5. Capacity asks'!$E$6:$E$305,"Outsourced") -> 0
A14: 2027 in-year cost (SAR '000) | B14: =SUM('5. Capacity asks'!$Q$6:$Q$305) -> 0 | C14: Part-year: a Q1 start costs four quarters, a Q4 start one.
A15: Full-year run-rate from 2028 (SAR '000) | B15: =SUM('5. Capacity asks'!$R$6:$R$305) -> 0
A17: Against your envelopes
A18: Test | B18: Your limit | C18: Your number | D18: Headroom | E18: Status
A19: 2027 cost (SAR '000) | B19: =CostEnvelope -> 4447 | C19: =$B$14 -> 0 | D19: =$B19-$C19 -> 4447 | E19: =IF($D19>=0,"Within envelope","Over envelope") -> Within envelope | F19: Positions can start later to bring this down.
A20: Net establishment change | B20: =HeadEnvelope -> 16 | C20: =SUM('5. Capacity asks'!$H$6:$H$305)-SUMIFS('4. Structure changes'!$H$5:$H$44,'4. Structure changes'!$B$5:$B$44,"Close")-SUMIFS('4. Structure changes'!$H$5:$H$44,'4. Structure changes'!$B$5:$B$44,"Merge into another unit") -> 0 | D20: =$B20-$C20 -> 16 | E20: =IF($D20>=0,"Within envelope","Over envelope") -> Within envelope | F20: Asks less the people released by closures and merges.
A21: Saudization | B21: =SaudiTarget -> 0.72 | C21: =($B$6+SUMIFS('5. Capacity asks'!$H$6:$H$305,'5. Capacity asks'!$F$6:$F$305,"Saudi"))/($B$5+SUM('5. Capacity asks'!$H$6:$H$305)) -> 0.62068966 | D21: =$C21-$B21 -> -0.099310345 | E21: =IF($C21>=$B21,"At or above target","Below target") -> Below target | F21: Projected on today's people plus everything you have asked for.
A23: What the ranking rule funds first | F23: Cut order runs bottom-up: 'Other' goes first, regulatory last.
A24: Priority | B24: FTE asked | C24: 2027 cost | D24: Cumulative cost | E24: Inside envelope?
A25: 1. Regulatory | B25: =SUMIFS('5. Capacity asks'!$H$6:$H$305,'5. Capacity asks'!$K$6:$K$305,"Regulatory") -> 0 | C25: =SUMIFS('5. Capacity asks'!$Q$6:$Q$305,'5. Capacity asks'!$K$6:$K$305,"Regulatory") -> 0 | D25: =SUM($C$25:$C25) -> 0 | E25: =IF($D25<=CostEnvelope,"Yes","No") -> Yes | F25: Mandated by SAMA or another regulator; not discretionary.
A26: 2. Risk | B26: =SUMIFS('5. Capacity asks'!$H$6:$H$305,'5. Capacity asks'!$K$6:$K$305,"Risk") -> 0 | C26: =SUMIFS('5. Capacity asks'!$Q$6:$Q$305,'5. Capacity asks'!$K$6:$K$305,"Risk") -> 0 | D26: =SUM($C$25:$C26) -> 0 | E26: =IF($D26<=CostEnvelope,"Yes","No") -> Yes | F26: Risk and control capacity, including audit finding remediation.
A27: 3. Revenue | B27: =SUMIFS('5. Capacity asks'!$H$6:$H$305,'5. Capacity asks'!$K$6:$K$305,"Revenue") -> 0 | C27: =SUMIFS('5. Capacity asks'!$Q$6:$Q$305,'5. Capacity asks'!$K$6:$K$305,"Revenue") -> 0 | D27: =SUM($C$25:$C27) -> 0 | E27: =IF($D27<=CostEnvelope,"Yes","No") -> Yes | F27: Directly linked to income — volume growth, new product, coverage.
A28: 4. Replacement | B28: =SUMIFS('5. Capacity asks'!$H$6:$H$305,'5. Capacity asks'!$K$6:$K$305,"Replacement") -> 0 | C28: =SUMIFS('5. Capacity asks'!$Q$6:$Q$305,'5. Capacity asks'!$K$6:$K$305,"Replacement") -> 0 | D28: =SUM($C$25:$C28) -> 0 | E28: =IF($D28<=CostEnvelope,"Yes","No") -> Yes | F28: Backfilling capacity the bank already had and has lost.
A29: 5. Efficiency | B29: =SUMIFS('5. Capacity asks'!$H$6:$H$305,'5. Capacity asks'!$K$6:$K$305,"Efficiency") -> 0 | C29: =SUMIFS('5. Capacity asks'!$Q$6:$Q$305,'5. Capacity asks'!$K$6:$K$305,"Efficiency") -> 0 | D29: =SUM($C$25:$C29) -> 0 | E29: =IF($D29<=CostEnvelope,"Yes","No") -> Yes | F29: Pays for itself through automation, centralisation or insourcing.
A30: 6. Other | B30: =SUMIFS('5. Capacity asks'!$H$6:$H$305,'5. Capacity asks'!$K$6:$K$305,"Other") -> 0 | C30: =SUMIFS('5. Capacity asks'!$Q$6:$Q$305,'5. Capacity asks'!$K$6:$K$305,"Other") -> 0 | D30: =SUM($C$25:$C30) -> 0 | E30: =IF($D30<=CostEnvelope,"Yes","No") -> Yes | F30: Everything else. First to be cut when the envelope binds.
A32: When the cost lands
A33: Start quarter | B33: FTE starting | C33: 2027 cost | D33: Run-rate added
A34: Q1 | B34: =SUMIFS('5. Capacity asks'!$H$6:$H$305,'5. Capacity asks'!$I$6:$I$305,"Q1") -> 0 | C34: =SUMIFS('5. Capacity asks'!$Q$6:$Q$305,'5. Capacity asks'!$I$6:$I$305,"Q1") -> 0 | D34: =SUMIFS('5. Capacity asks'!$R$6:$R$305,'5. Capacity asks'!$I$6:$I$305,"Q1") -> 0
A35: Q2 | B35: =SUMIFS('5. Capacity asks'!$H$6:$H$305,'5. Capacity asks'!$I$6:$I$305,"Q2") -> 0 | C35: =SUMIFS('5. Capacity asks'!$Q$6:$Q$305,'5. Capacity asks'!$I$6:$I$305,"Q2") -> 0 | D35: =SUMIFS('5. Capacity asks'!$R$6:$R$305,'5. Capacity asks'!$I$6:$I$305,"Q2") -> 0
A36: Q3 | B36: =SUMIFS('5. Capacity asks'!$H$6:$H$305,'5. Capacity asks'!$I$6:$I$305,"Q3") -> 0 | C36: =SUMIFS('5. Capacity asks'!$Q$6:$Q$305,'5. Capacity asks'!$I$6:$I$305,"Q3") -> 0 | D36: =SUMIFS('5. Capacity asks'!$R$6:$R$305,'5. Capacity asks'!$I$6:$I$305,"Q3") -> 0
A37: Q4 | B37: =SUMIFS('5. Capacity asks'!$H$6:$H$305,'5. Capacity asks'!$I$6:$I$305,"Q4") -> 0 | C37: =SUMIFS('5. Capacity asks'!$Q$6:$Q$305,'5. Capacity asks'!$I$6:$I$305,"Q4") -> 0 | D37: =SUMIFS('5. Capacity asks'!$R$6:$R$305,'5. Capacity asks'!$I$6:$I$305,"Q4") -> 0
A39: Demand against capacity, by driver
A40: Workload driver | B40: Units | C40: Filled today | D40: 2027 FTE required | E40: Modelled gap
A41: Accounts serviced | B41: =COUNTIF('2. Current capacity'!$E$5:$E$31,"Accounts serviced") -> 0 | C41: =SUMIFS('2. Current capacity'!$C$5:$C$31,'2. Current capacity'!$E$5:$E$31,"Accounts serviced") -> 0 | D41: =SUMIFS('2. Current capacity'!$L$5:$L$31,'2. Current capacity'!$E$5:$E$31,"Accounts serviced") -> 0 | E41: =SUMIFS('2. Current capacity'!$M$5:$M$31,'2. Current capacity'!$E$5:$E$31,"Accounts serviced") -> 0 | F41: accounts
A42: Transactions processed | B42: =COUNTIF('2. Current capacity'!$E$5:$E$31,"Transactions processed") -> 0 | C42: =SUMIFS('2. Current capacity'!$C$5:$C$31,'2. Current capacity'!$E$5:$E$31,"Transactions processed") -> 0 | D42: =SUMIFS('2. Current capacity'!$L$5:$L$31,'2. Current capacity'!$E$5:$E$31,"Transactions processed") -> 0 | E42: =SUMIFS('2. Current capacity'!$M$5:$M$31,'2. Current capacity'!$E$5:$E$31,"Transactions processed") -> 0 | F42: transactions / yr
A43: Applications processed | B43: =COUNTIF('2. Current capacity'!$E$5:$E$31,"Applications processed") -> 0 | C43: =SUMIFS('2. Current capacity'!$C$5:$C$31,'2. Current capacity'!$E$5:$E$31,"Applications processed") -> 0 | D43: =SUMIFS('2. Current capacity'!$L$5:$L$31,'2. Current capacity'!$E$5:$E$31,"Applications processed") -> 0 | E43: =SUMIFS('2. Current capacity'!$M$5:$M$31,'2. Current capacity'!$E$5:$E$31,"Applications processed") -> 0 | F43: applications / yr
A44: Payments processed | B44: =COUNTIF('2. Current capacity'!$E$5:$E$31,"Payments processed") -> 0 | C44: =SUMIFS('2. Current capacity'!$C$5:$C$31,'2. Current capacity'!$E$5:$E$31,"Payments processed") -> 0 | D44: =SUMIFS('2. Current capacity'!$L$5:$L$31,'2. Current capacity'!$E$5:$E$31,"Payments processed") -> 0 | E44: =SUMIFS('2. Current capacity'!$M$5:$M$31,'2. Current capacity'!$E$5:$E$31,"Payments processed") -> 0 | F44: payments / yr
A45: Cases or tickets handled | B45: =COUNTIF('2. Current capacity'!$E$5:$E$31,"Cases or tickets handled") -> 0 | C45: =SUMIFS('2. Current capacity'!$C$5:$C$31,'2. Current capacity'!$E$5:$E$31,"Cases or tickets handled") -> 0 | D45: =SUMIFS('2. Current capacity'!$L$5:$L$31,'2. Current capacity'!$E$5:$E$31,"Cases or tickets handled") -> 0 | E45: =SUMIFS('2. Current capacity'!$M$5:$M$31,'2. Current capacity'!$E$5:$E$31,"Cases or tickets handled") -> 0 | F45: cases / yr
A46: Calls handled | B46: =COUNTIF('2. Current capacity'!$E$5:$E$31,"Calls handled") -> 0 | C46: =SUMIFS('2. Current capacity'!$C$5:$C$31,'2. Current capacity'!$E$5:$E$31,"Calls handled") -> 0 | D46: =SUMIFS('2. Current capacity'!$L$5:$L$31,'2. Current capacity'!$E$5:$E$31,"Calls handled") -> 0 | E46: =SUMIFS('2. Current capacity'!$M$5:$M$31,'2. Current capacity'!$E$5:$E$31,"Calls handled") -> 0 | F46: calls / yr
...

Sheet 7. Check & submit
A1: Check & submit
A2: Work down this sheet until every blocking check reads OK, then set the state at the bottom to Submitted and return the file.
A4: Blocking — these must be clear
A5: Check | B5: Count | C5: Status | D5: What to do
A6: Ask rows with something missing | B6: =COUNTIF('5. Capacity asks'!$S$6:$S$305,"?*") -> 0 | C6: =IF($B6=0,"OK","Fix") -> OK | D6: Sheet 5 lists what each row is missing in the last two columns. Filter on 'What's missing' to find them.
A7: Ask rows naming a unit that does not exist | B7: =SUMPRODUCT(('5. Capacity asks'!$B$6:$B$305<>"")*(COUNTIF(UnitList,'5. Capacity asks'!$B$6:$B$305)=0)*(COUNTIF('4. Structure changes'!$J$5:$J$44,'5. Capacity asks'!$B$6:$B$305)=0)) -> 0 | C7: =IF($B7=0,"OK","Fix") -> OK | D7: Either pick an existing unit, or add the new unit on sheet 4 and use its change ID.
A8: 2026 vacancies not yet confirmed | B8: =COUNTBLANK('3. Attrition & pipeline'!$E$77:$E$111) -> 35 | C8: =IF($B8=0,"OK","Fix") -> Fix | D8: Sheet 3. Anything you do not confirm lapses and will not carry into 2027.
A9: Named leavers with no backfill answer | B9: =SUMPRODUCT(('3. Attrition & pipeline'!$B$14:$B$73<>"")*('3. Attrition & pipeline'!$G$14:$G$73="")) -> 0 | C9: =IF($B9=0,"OK","Fix") -> OK | D9: Sheet 3. Say whether each departure needs replacing.
A10: Units with no workload driver | B10: =SUMPRODUCT(('2. Current capacity'!$A$5:$A$31<>"")*('2. Current capacity'!$E$5:$E$31="")) -> 27 | C10: =IF($B10=0,"OK","Fix") -> Fix | D10: Sheet 2. Every unit needs the one thing that drives its work.
A11: Units with a driver but missing volumes | B11: =SUMPRODUCT(('2. Current capacity'!$E$5:$E$31<>"")*((('2. Current capacity'!$F$5:$F$31="")+('2. Current capacity'!$G$5:$G$31="")+('2. Current capacity'!$I$5:$I$31=""))>0)) -> 0 | C11: =IF($B11=0,"OK","Fix") -> OK | D11: Sheet 2 needs the 2026 volume, the 2027 expected volume and the FTE doing that work.
A12: Structure changes started but incomplete | B12: =SUMPRODUCT(('4. Structure changes'!$B$5:$B$44<>"")*((('4. Structure changes'!$C$5:$C$44="")+('4. Structure changes'!$D$5:$D$44="")+('4. Structure changes'!$G$5:$G$44=""))>0)) -> 0 | C12: =IF($B12=0,"OK","Fix") -> OK | D12: Sheet 4. A change needs a unit name, a level and a reason.
A14: Worth a look — these do not block you
A15: Check | B15: Count | C15: Status | D15: What to do
A16: Cost above your envelope | B16: =IF('6. My position'!$C$19>'6. My position'!$B$19,1,0) -> 0 | C16: =IF($B16=0,"OK","Review") -> OK | D16: Move start quarters later, or say on sheet 5 why the envelope has to move.
A17: Net establishment change above your envelope | B17: =IF('6. My position'!$C$20>'6. My position'!$B$20,1,0) -> 0 | C17: =IF($B17=0,"OK","Review") -> OK | D17: Convert, insource or close somewhere else to pay for it.
A18: Saudization below your target | B18: =IF('6. My position'!$C$21<'6. My position'!$B$21,1,0) -> 1 | C18: =IF($B18=0,"OK","Review") -> Review | D18: Change the intended basis on sheet 5, or explain the gap when you submit.
A20: The rows that need attention | D20: The first 25. Clear these and the rest appear.
A21: Ask ref | B21: Unit | C21: Job title | D21: What is missing
A22: =IFERROR(IF(INDEX('5. Capacity asks'!$A$6:$A$305,MATCH(1,'5. Capacity asks'!$T$6:$T$305,0))=0,"",INDEX('5. Capacity asks'!$A$6:$A$305,MATCH(1,'5. Capacity asks'!$T$6:$T$305,0))),"") | B22: =IFERROR(IF(INDEX('5. Capacity asks'!$B$6:$B$305,MATCH(1,'5. Capacity asks'!$T$6:$T$305,0))=0,"",INDEX('5. Capacity asks'!$B$6:$B$305,MATCH(1,'5. Capacity asks'!$T$6:$T$305,0))),"") | C22: =IFERROR(IF(INDEX('5. Capacity asks'!$C$6:$C$305,MATCH(1,'5. Capacity asks'!$T$6:$T$305,0))=0,"",INDEX('5. Capacity asks'!$C$6:$C$305,MATCH(1,'5. Capacity asks'!$T$6:$T$305,0))),"") | D22: =IFERROR(IF(INDEX('5. Capacity asks'!$S$6:$S$305,MATCH(1,'5. Capacity asks'!$T$6:$T$305,0))=0,"",INDEX('5. Capacity asks'!$S$6:$S$305,MATCH(1,'5. Capacity asks'!$T$6:$T$305,0))),"")
A23: =IFERROR(IF(INDEX('5. Capacity asks'!$A$6:$A$305,MATCH(2,'5. Capacity asks'!$T$6:$T$305,0))=0,"",INDEX('5. Capacity asks'!$A$6:$A$305,MATCH(2,'5. Capacity asks'!$T$6:$T$305,0))),"") | B23: =IFERROR(IF(INDEX('5. Capacity asks'!$B$6:$B$305,MATCH(2,'5. Capacity asks'!$T$6:$T$305,0))=0,"",INDEX('5. Capacity asks'!$B$6:$B$305,MATCH(2,'5. Capacity asks'!$T$6:$T$305,0))),"") | C23: =IFERROR(IF(INDEX('5. Capacity asks'!$C$6:$C$305,MATCH(2,'5. Capacity asks'!$T$6:$T$305,0))=0,"",INDEX('5. Capacity asks'!$C$6:$C$305,MATCH(2,'5. Capacity asks'!$T$6:$T$305,0))),"") | D23: =IFERROR(IF(INDEX('5. Capacity asks'!$S$6:$S$305,MATCH(2,'5. Capacity asks'!$T$6:$T$305,0))=0,"",INDEX('5. Capacity asks'!$S$6:$S$305,MATCH(2,'5. Capacity asks'!$T$6:$T$305,0))),"")
A24: =IFERROR(IF(INDEX('5. Capacity asks'!$A$6:$A$305,MATCH(3,'5. Capacity asks'!$T$6:$T$305,0))=0,"",INDEX('5. Capacity asks'!$A$6:$A$305,MATCH(3,'5. Capacity asks'!$T$6:$T$305,0))),"") | B24: =IFERROR(IF(INDEX('5. Capacity asks'!$B$6:$B$305,MATCH(3,'5. Capacity asks'!$T$6:$T$305,0))=0,"",INDEX('5. Capacity asks'!$B$6:$B$305,MATCH(3,'5. Capacity asks'!$T$6:$T$305,0))),"") | C24: =IFERROR(IF(INDEX('5. Capacity asks'!$C$6:$C$305,MATCH(3,'5. Capacity asks'!$T$6:$T$305,0))=0,"",INDEX('5. Capacity asks'!$C$6:$C$305,MATCH(3,'5. Capacity asks'!$T$6:$T$305,0))),"") | D24: =IFERROR(IF(INDEX('5. Capacity asks'!$S$6:$S$305,MATCH(3,'5. Capacity asks'!$T$6:$T$305,0))=0,"",INDEX('5. Capacity asks'!$S$6:$S$305,MATCH(3,'5. Capacity asks'!$T$6:$T$305,0))),"")
A25: =IFERROR(IF(INDEX('5. Capacity asks'!$A$6:$A$305,MATCH(4,'5. Capacity asks'!$T$6:$T$305,0))=0,"",INDEX('5. Capacity asks'!$A$6:$A$305,MATCH(4,'5. Capacity asks'!$T$6:$T$305,0))),"") | B25: =IFERROR(IF(INDEX('5. Capacity asks'!$B$6:$B$305,MATCH(4,'5. Capacity asks'!$T$6:$T$305,0))=0,"",INDEX('5. Capacity asks'!$B$6:$B$305,MATCH(4,'5. Capacity asks'!$T$6:$T$305,0))),"") | C25: =IFERROR(IF(INDEX('5. Capacity asks'!$C$6:$C$305,MATCH(4,'5. Capacity asks'!$T$6:$T$305,0))=0,"",INDEX('5. Capacity asks'!$C$6:$C$305,MATCH(4,'5. Capacity asks'!$T$6:$T$305,0))),"") | D25: =IFERROR(IF(INDEX('5. Capacity asks'!$S$6:$S$305,MATCH(4,'5. Capacity asks'!$T$6:$T$305,0))=0,"",INDEX('5. Capacity asks'!$S$6:$S$305,MATCH(4,'5. Capacity asks'!$T$6:$T$305,0))),"")
A26: =IFERROR(IF(INDEX('5. Capacity asks'!$A$6:$A$305,MATCH(5,'5. Capacity asks'!$T$6:$T$305,0))=0,"",INDEX('5. Capacity asks'!$A$6:$A$305,MATCH(5,'5. Capacity asks'!$T$6:$T$305,0))),"") | B26: =IFERROR(IF(INDEX('5. Capacity asks'!$B$6:$B$305,MATCH(5,'5. Capacity asks'!$T$6:$T$305,0))=0,"",INDEX('5. Capacity asks'!$B$6:$B$305,MATCH(5,'5. Capacity asks'!$T$6:$T$305,0))),"") | C26: =IFERROR(IF(INDEX('5. Capacity asks'!$C$6:$C$305,MATCH(5,'5. Capacity asks'!$T$6:$T$305,0))=0,"",INDEX('5. Capacity asks'!$C$6:$C$305,MATCH(5,'5. Capacity asks'!$T$6:$T$305,0))),"") | D26: =IFERROR(IF(INDEX('5. Capacity asks'!$S$6:$S$305,MATCH(5,'5. Capacity asks'!$T$6:$T$305,0))=0,"",INDEX('5. Capacity asks'!$S$6:$S$305,MATCH(5,'5. Capacity asks'!$T$6:$T$305,0))),"")
A27: =IFERROR(IF(INDEX('5. Capacity asks'!$A$6:$A$305,MATCH(6,'5. Capacity asks'!$T$6:$T$305,0))=0,"",INDEX('5. Capacity asks'!$A$6:$A$305,MATCH(6,'5. Capacity asks'!$T$6:$T$305,0))),"") | B27: =IFERROR(IF(INDEX('5. Capacity asks'!$B$6:$B$305,MATCH(6,'5. Capacity asks'!$T$6:$T$305,0))=0,"",INDEX('5. Capacity asks'!$B$6:$B$305,MATCH(6,'5. Capacity asks'!$T$6:$T$305,0))),"") | C27: =IFERROR(IF(INDEX('5. Capacity asks'!$C$6:$C$305,MATCH(6,'5. Capacity asks'!$T$6:$T$305,0))=0,"",INDEX('5. Capacity asks'!$C$6:$C$305,MATCH(6,'5. Capacity asks'!$T$6:$T$305,0))),"") | D27: =IFERROR(IF(INDEX('5. Capacity asks'!$S$6:$S$305,MATCH(6,'5. Capacity asks'!$T$6:$T$305,0))=0,"",INDEX('5. Capacity asks'!$S$6:$S$305,MATCH(6,'5. Capacity asks'!$T$6:$T$305,0))),"")
A28: =IFERROR(IF(INDEX('5. Capacity asks'!$A$6:$A$305,MATCH(7,'5. Capacity asks'!$T$6:$T$305,0))=0,"",INDEX('5. Capacity asks'!$A$6:$A$305,MATCH(7,'5. Capacity asks'!$T$6:$T$305,0))),"") | B28: =IFERROR(IF(INDEX('5. Capacity asks'!$B$6:$B$305,MATCH(7,'5. Capacity asks'!$T$6:$T$305,0))=0,"",INDEX('5. Capacity asks'!$B$6:$B$305,MATCH(7,'5. Capacity asks'!$T$6:$T$305,0))),"") | C28: =IFERROR(IF(INDEX('5. Capacity asks'!$C$6:$C$305,MATCH(7,'5. Capacity asks'!$T$6:$T$305,0))=0,"",INDEX('5. Capacity asks'!$C$6:$C$305,MATCH(7,'5. Capacity asks'!$T$6:$T$305,0))),"") | D28: =IFERROR(IF(INDEX('5. Capacity asks'!$S$6:$S$305,MATCH(7,'5. Capacity asks'!$T$6:$T$305,0))=0,"",INDEX('5. Capacity asks'!$S$6:$S$305,MATCH(7,'5. Capacity asks'!$T$6:$T$305,0))),"")
A29: =IFERROR(IF(INDEX('5. Capacity asks'!$A$6:$A$305,MATCH(8,'5. Capacity asks'!$T$6:$T$305,0))=0,"",INDEX('5. Capacity asks'!$A$6:$A$305,MATCH(8,'5. Capacity asks'!$T$6:$T$305,0))),"") | B29: =IFERROR(IF(INDEX('5. Capacity asks'!$B$6:$B$305,MATCH(8,'5. Capacity asks'!$T$6:$T$305,0))=0,"",INDEX('5. Capacity asks'!$B$6:$B$305,MATCH(8,'5. Capacity asks'!$T$6:$T$305,0))),"") | C29: =IFERROR(IF(INDEX('5. Capacity asks'!$C$6:$C$305,MATCH(8,'5. Capacity asks'!$T$6:$T$305,0))=0,"",INDEX('5. Capacity asks'!$C$6:$C$305,MATCH(8,'5. Capacity asks'!$T$6:$T$305,0))),"") | D29: =IFERROR(IF(INDEX('5. Capacity asks'!$S$6:$S$305,MATCH(8,'5. Capacity asks'!$T$6:$T$305,0))=0,"",INDEX('5. Capacity asks'!$S$6:$S$305,MATCH(8,'5. Capacity asks'!$T$6:$T$305,0))),"")
A30: =IFERROR(IF(INDEX('5. Capacity asks'!$A$6:$A$305,MATCH(9,'5. Capacity asks'!$T$6:$T$305,0))=0,"",INDEX('5. Capacity asks'!$A$6:$A$305,MATCH(9,'5. Capacity asks'!$T$6:$T$305,0))),"") | B30: =IFERROR(IF(INDEX('5. Capacity asks'!$B$6:$B$305,MATCH(9,'5. Capacity asks'!$T$6:$T$305,0))=0,"",INDEX('5. Capacity asks'!$B$6:$B$305,MATCH(9,'5. Capacity asks'!$T$6:$T$305,0))),"") | C30: =IFERROR(IF(INDEX('5. Capacity asks'!$C$6:$C$305,MATCH(9,'5. Capacity asks'!$T$6:$T$305,0))=0,"",INDEX('5. Capacity asks'!$C$6:$C$305,MATCH(9,'5. Capacity asks'!$T$6:$T$305,0))),"") | D30: =IFERROR(IF(INDEX('5. Capacity asks'!$S$6:$S$305,MATCH(9,'5. Capacity asks'!$T$6:$T$305,0))=0,"",INDEX('5. Capacity asks'!$S$6:$S$305,MATCH(9,'5. Capacity asks'!$T$6:$T$305,0))),"")
A31: =IFERROR(IF(INDEX('5. Capacity asks'!$A$6:$A$305,MATCH(10,'5. Capacity asks'!$T$6:$T$305,0))=0,"",INDEX('5. Capacity asks'!$A$6:$A$305,MATCH(10,'5. Capacity asks'!$T$6:$T$305,0))),"") | B31: =IFERROR(IF(INDEX('5. Capacity asks'!$B$6:$B$305,MATCH(10,'5. Capacity asks'!$T$6:$T$305,0))=0,"",INDEX('5. Capacity asks'!$B$6:$B$305,MATCH(10,'5. Capacity asks'!$T$6:$T$305,0))),"") | C31: =IFERROR(IF(INDEX('5. Capacity asks'!$C$6:$C$305,MATCH(10,'5. Capacity asks'!$T$6:$T$305,0))=0,"",INDEX('5. Capacity asks'!$C$6:$C$305,MATCH(10,'5. Capacity asks'!$T$6:$T$305,0))),"") | D31: =IFERROR(IF(INDEX('5. Capacity asks'!$S$6:$S$305,MATCH(10,'5. Capacity asks'!$T$6:$T$305,0))=0,"",INDEX('5. Capacity asks'!$S$6:$S$305,MATCH(10,'5. Capacity asks'!$T$6:$T$305,0))),"")
A32: =IFERROR(IF(INDEX('5. Capacity asks'!$A$6:$A$305,MATCH(11,'5. Capacity asks'!$T$6:$T$305,0))=0,"",INDEX('5. Capacity asks'!$A$6:$A$305,MATCH(11,'5. Capacity asks'!$T$6:$T$305,0))),"") | B32: =IFERROR(IF(INDEX('5. Capacity asks'!$B$6:$B$305,MATCH(11,'5. Capacity asks'!$T$6:$T$305,0))=0,"",INDEX('5. Capacity asks'!$B$6:$B$305,MATCH(11,'5. Capacity asks'!$T$6:$T$305,0))),"") | C32: =IFERROR(IF(INDEX('5. Capacity asks'!$C$6:$C$305,MATCH(11,'5. Capacity asks'!$T$6:$T$305,0))=0,"",INDEX('5. Capacity asks'!$C$6:$C$305,MATCH(11,'5. Capacity asks'!$T$6:$T$305,0))),"") | D32: =IFERROR(IF(INDEX('5. Capacity asks'!$S$6:$S$305,MATCH(11,'5. Capacity asks'!$T$6:$T$305,0))=0,"",INDEX('5. Capacity asks'!$S$6:$S$305,MATCH(11,'5. Capacity asks'!$T$6:$T$305,0))),"")
A33: =IFERROR(IF(INDEX('5. Capacity asks'!$A$6:$A$305,MATCH(12,'5. Capacity asks'!$T$6:$T$305,0))=0,"",INDEX('5. Capacity asks'!$A$6:$A$305,MATCH(12,'5. Capacity asks'!$T$6:$T$305,0))),"") | B33: =IFERROR(IF(INDEX('5. Capacity asks'!$B$6:$B$305,MATCH(12,'5. Capacity asks'!$T$6:$T$305,0))=0,"",INDEX('5. Capacity asks'!$B$6:$B$305,MATCH(12,'5. Capacity asks'!$T$6:$T$305,0))),"") | C33: =IFERROR(IF(INDEX('5. Capacity asks'!$C$6:$C$305,MATCH(12,'5. Capacity asks'!$T$6:$T$305,0))=0,"",INDEX('5. Capacity asks'!$C$6:$C$305,MATCH(12,'5. Capacity asks'!$T$6:$T$305,0))),"") | D33: =IFERROR(IF(INDEX('5. Capacity asks'!$S$6:$S$305,MATCH(12,'5. Capacity asks'!$T$6:$T$305,0))=0,"",INDEX('5. Capacity asks'!$S$6:$S$305,MATCH(12,'5. Capacity asks'!$T$6:$T$305,0))),"")
A34: =IFERROR(IF(INDEX('5. Capacity asks'!$A$6:$A$305,MATCH(13,'5. Capacity asks'!$T$6:$T$305,0))=0,"",INDEX('5. Capacity asks'!$A$6:$A$305,MATCH(13,'5. Capacity asks'!$T$6:$T$305,0))),"") | B34: =IFERROR(IF(INDEX('5. Capacity asks'!$B$6:$B$305,MATCH(13,'5. Capacity asks'!$T$6:$T$305,0))=0,"",INDEX('5. Capacity asks'!$B$6:$B$305,MATCH(13,'5. Capacity asks'!$T$6:$T$305,0))),"") | C34: =IFERROR(IF(INDEX('5. Capacity asks'!$C$6:$C$305,MATCH(13,'5. Capacity asks'!$T$6:$T$305,0))=0,"",INDEX('5. Capacity asks'!$C$6:$C$305,MATCH(13,'5. Capacity asks'!$T$6:$T$305,0))),"") | D34: =IFERROR(IF(INDEX('5. Capacity asks'!$S$6:$S$305,MATCH(13,'5. Capacity asks'!$T$6:$T$305,0))=0,"",INDEX('5. Capacity asks'!$S$6:$S$305,MATCH(13,'5. Capacity asks'!$T$6:$T$305,0))),"")
A35: =IFERROR(IF(INDEX('5. Capacity asks'!$A$6:$A$305,MATCH(14,'5. Capacity asks'!$T$6:$T$305,0))=0,"",INDEX('5. Capacity asks'!$A$6:$A$305,MATCH(14,'5. Capacity asks'!$T$6:$T$305,0))),"") | B35: =IFERROR(IF(INDEX('5. Capacity asks'!$B$6:$B$305,MATCH(14,'5. Capacity asks'!$T$6:$T$305,0))=0,"",INDEX('5. Capacity asks'!$B$6:$B$305,MATCH(14,'5. Capacity asks'!$T$6:$T$305,0))),"") | C35: =IFERROR(IF(INDEX('5. Capacity asks'!$C$6:$C$305,MATCH(14,'5. Capacity asks'!$T$6:$T$305,0))=0,"",INDEX('5. Capacity asks'!$C$6:$C$305,MATCH(14,'5. Capacity asks'!$T$6:$T$305,0))),"") | D35: =IFERROR(IF(INDEX('5. Capacity asks'!$S$6:$S$305,MATCH(14,'5. Capacity asks'!$T$6:$T$305,0))=0,"",INDEX('5. Capacity asks'!$S$6:$S$305,MATCH(14,'5. Capacity asks'!$T$6:$T$305,0))),"")
A36: =IFERROR(IF(INDEX('5. Capacity asks'!$A$6:$A$305,MATCH(15,'5. Capacity asks'!$T$6:$T$305,0))=0,"",INDEX('5. Capacity asks'!$A$6:$A$305,MATCH(15,'5. Capacity asks'!$T$6:$T$305,0))),"") | B36: =IFERROR(IF(INDEX('5. Capacity asks'!$B$6:$B$305,MATCH(15,'5. Capacity asks'!$T$6:$T$305,0))=0,"",INDEX('5. Capacity asks'!$B$6:$B$305,MATCH(15,'5. Capacity asks'!$T$6:$T$305,0))),"") | C36: =IFERROR(IF(INDEX('5. Capacity asks'!$C$6:$C$305,MATCH(15,'5. Capacity asks'!$T$6:$T$305,0))=0,"",INDEX('5. Capacity asks'!$C$6:$C$305,MATCH(15,'5. Capacity asks'!$T$6:$T$305,0))),"") | D36: =IFERROR(IF(INDEX('5. Capacity asks'!$S$6:$S$305,MATCH(15,'5. Capacity asks'!$T$6:$T$305,0))=0,"",INDEX('5. Capacity asks'!$S$6:$S$305,MATCH(15,'5. Capacity asks'!$T$6:$T$305,0))),"")
A37: =IFERROR(IF(INDEX('5. Capacity asks'!$A$6:$A$305,MATCH(16,'5. Capacity asks'!$T$6:$T$305,0))=0,"",INDEX('5. Capacity asks'!$A$6:$A$305,MATCH(16,'5. Capacity asks'!$T$6:$T$305,0))),"") | B37: =IFERROR(IF(INDEX('5. Capacity asks'!$B$6:$B$305,MATCH(16,'5. Capacity asks'!$T$6:$T$305,0))=0,"",INDEX('5. Capacity asks'!$B$6:$B$305,MATCH(16,'5. Capacity asks'!$T$6:$T$305,0))),"") | C37: =IFERROR(IF(INDEX('5. Capacity asks'!$C$6:$C$305,MATCH(16,'5. Capacity asks'!$T$6:$T$305,0))=0,"",INDEX('5. Capacity asks'!$C$6:$C$305,MATCH(16,'5. Capacity asks'!$T$6:$T$305,0))),"") | D37: =IFERROR(IF(INDEX('5. Capacity asks'!$S$6:$S$305,MATCH(16,'5. Capacity asks'!$T$6:$T$305,0))=0,"",INDEX('5. Capacity asks'!$S$6:$S$305,MATCH(16,'5. Capacity asks'!$T$6:$T$305,0))),"")
A38: =IFERROR(IF(INDEX('5. Capacity asks'!$A$6:$A$305,MATCH(17,'5. Capacity asks'!$T$6:$T$305,0))=0,"",INDEX('5. Capacity asks'!$A$6:$A$305,MATCH(17,'5. Capacity asks'!$T$6:$T$305,0))),"") | B38: =IFERROR(IF(INDEX('5. Capacity asks'!$B$6:$B$305,MATCH(17,'5. Capacity asks'!$T$6:$T$305,0))=0,"",INDEX('5. Capacity asks'!$B$6:$B$305,MATCH(17,'5. Capacity asks'!$T$6:$T$305,0))),"") | C38: =IFERROR(IF(INDEX('5. Capacity asks'!$C$6:$C$305,MATCH(17,'5. Capacity asks'!$T$6:$T$305,0))=0,"",INDEX('5. Capacity asks'!$C$6:$C$305,MATCH(17,'5. Capacity asks'!$T$6:$T$305,0))),"") | D38: =IFERROR(IF(INDEX('5. Capacity asks'!$S$6:$S$305,MATCH(17,'5. Capacity asks'!$T$6:$T$305,0))=0,"",INDEX('5. Capacity asks'!$S$6:$S$305,MATCH(17,'5. Capacity asks'!$T$6:$T$305,0))),"")
A39: =IFERROR(IF(INDEX('5. Capacity asks'!$A$6:$A$305,MATCH(18,'5. Capacity asks'!$T$6:$T$305,0))=0,"",INDEX('5. Capacity asks'!$A$6:$A$305,MATCH(18,'5. Capacity asks'!$T$6:$T$305,0))),"") | B39: =IFERROR(IF(INDEX('5. Capacity asks'!$B$6:$B$305,MATCH(18,'5. Capacity asks'!$T$6:$T$305,0))=0,"",INDEX('5. Capacity asks'!$B$6:$B$305,MATCH(18,'5. Capacity asks'!$T$6:$T$305,0))),"") | C39: =IFERROR(IF(INDEX('5. Capacity asks'!$C$6:$C$305,MATCH(18,'5. Capacity asks'!$T$6:$T$305,0))=0,"",INDEX('5. Capacity asks'!$C$6:$C$305,MATCH(18,'5. Capacity asks'!$T$6:$T$305,0))),"") | D39: =IFERROR(IF(INDEX('5. Capacity asks'!$S$6:$S$305,MATCH(18,'5. Capacity asks'!$T$6:$T$305,0))=0,"",INDEX('5. Capacity asks'!$S$6:$S$305,MATCH(18,'5. Capacity asks'!$T$6:$T$305,0))),"")
A40: =IFERROR(IF(INDEX('5. Capacity asks'!$A$6:$A$305,MATCH(19,'5. Capacity asks'!$T$6:$T$305,0))=0,"",INDEX('5. Capacity asks'!$A$6:$A$305,MATCH(19,'5. Capacity asks'!$T$6:$T$305,0))),"") | B40: =IFERROR(IF(INDEX('5. Capacity asks'!$B$6:$B$305,MATCH(19,'5. Capacity asks'!$T$6:$T$305,0))=0,"",INDEX('5. Capacity asks'!$B$6:$B$305,MATCH(19,'5. Capacity asks'!$T$6:$T$305,0))),"") | C40: =IFERROR(IF(INDEX('5. Capacity asks'!$C$6:$C$305,MATCH(19,'5. Capacity asks'!$T$6:$T$305,0))=0,"",INDEX('5. Capacity asks'!$C$6:$C$305,MATCH(19,'5. Capacity asks'!$T$6:$T$305,0))),"") | D40: =IFERROR(IF(INDEX('5. Capacity asks'!$S$6:$S$305,MATCH(19,'5. Capacity asks'!$T$6:$T$305,0))=0,"",INDEX('5. Capacity asks'!$S$6:$S$305,MATCH(19,'5. Capacity asks'!$T$6:$T$305,0))),"")
A41: =IFERROR(IF(INDEX('5. Capacity asks'!$A$6:$A$305,MATCH(20,'5. Capacity asks'!$T$6:$T$305,0))=0,"",INDEX('5. Capacity asks'!$A$6:$A$305,MATCH(20,'5. Capacity asks'!$T$6:$T$305,0))),"") | B41: =IFERROR(IF(INDEX('5. Capacity asks'!$B$6:$B$305,MATCH(20,'5. Capacity asks'!$T$6:$T$305,0))=0,"",INDEX('5. Capacity asks'!$B$6:$B$305,MATCH(20,'5. Capacity asks'!$T$6:$T$305,0))),"") | C41: =IFERROR(IF(INDEX('5. Capacity asks'!$C$6:$C$305,MATCH(20,'5. Capacity asks'!$T$6:$T$305,0))=0,"",INDEX('5. Capacity asks'!$C$6:$C$305,MATCH(20,'5. Capacity asks'!$T$6:$T$305,0))),"") | D41: =IFERROR(IF(INDEX('5. Capacity asks'!$S$6:$S$305,MATCH(20,'5. Capacity asks'!$T$6:$T$305,0))=0,"",INDEX('5. Capacity asks'!$S$6:$S$305,MATCH(20,'5. Capacity asks'!$T$6:$T$305,0))),"")
A42: =IFERROR(IF(INDEX('5. Capacity asks'!$A$6:$A$305,MATCH(21,'5. Capacity asks'!$T$6:$T$305,0))=0,"",INDEX('5. Capacity asks'!$A$6:$A$305,MATCH(21,'5. Capacity asks'!$T$6:$T$305,0))),"") | B42: =IFERROR(IF(INDEX('5. Capacity asks'!$B$6:$B$305,MATCH(21,'5. Capacity asks'!$T$6:$T$305,0))=0,"",INDEX('5. Capacity asks'!$B$6:$B$305,MATCH(21,'5. Capacity asks'!$T$6:$T$305,0))),"") | C42: =IFERROR(IF(INDEX('5. Capacity asks'!$C$6:$C$305,MATCH(21,'5. Capacity asks'!$T$6:$T$305,0))=0,"",INDEX('5. Capacity asks'!$C$6:$C$305,MATCH(21,'5. Capacity asks'!$T$6:$T$305,0))),"") | D42: =IFERROR(IF(INDEX('5. Capacity asks'!$S$6:$S$305,MATCH(21,'5. Capacity asks'!$T$6:$T$305,0))=0,"",INDEX('5. Capacity asks'!$S$6:$S$305,MATCH(21,'5. Capacity asks'!$T$6:$T$305,0))),"")
A43: =IFERROR(IF(INDEX('5. Capacity asks'!$A$6:$A$305,MATCH(22,'5. Capacity asks'!$T$6:$T$305,0))=0,"",INDEX('5. Capacity asks'!$A$6:$A$305,MATCH(22,'5. Capacity asks'!$T$6:$T$305,0))),"") | B43: =IFERROR(IF(INDEX('5. Capacity asks'!$B$6:$B$305,MATCH(22,'5. Capacity asks'!$T$6:$T$305,0))=0,"",INDEX('5. Capacity asks'!$B$6:$B$305,MATCH(22,'5. Capacity asks'!$T$6:$T$305,0))),"") | C43: =IFERROR(IF(INDEX('5. Capacity asks'!$C$6:$C$305,MATCH(22,'5. Capacity asks'!$T$6:$T$305,0))=0,"",INDEX('5. Capacity asks'!$C$6:$C$305,MATCH(22,'5. Capacity asks'!$T$6:$T$305,0))),"") | D43: =IFERROR(IF(INDEX('5. Capacity asks'!$S$6:$S$305,MATCH(22,'5. Capacity asks'!$T$6:$T$305,0))=0,"",INDEX('5. Capacity asks'!$S$6:$S$305,MATCH(22,'5. Capacity asks'!$T$6:$T$305,0))),"")
...

Sheet Ref
A1: Reference data
A2: Do not edit. Maintained centrally.
A4: Settings
A5: Plan year | B5: 2027
A6: Base year | B6: 2026
A7: Group | B7: Risk Group
A8: Attrition rate (bank default) | B8: 0.09
A9: Productivity uplift (bank default) | B9: 0.03
A10: Salary inflation | B10: 0.04
A11: Employer GOSI - Saudi | B11: 0.1175
A12: Employer GOSI - non-Saudi | B12: 0.02
A13: One-off cost - grade below G14 | B13: 12
A14: One-off cost - grade G14 and above | B14: 45
A16: Envelope for this group
A17: Cost envelope (SAR '000) | B17: 4447
A18: Headcount envelope (net adds) | B18: 16
A19: Saudization target | B19: 0.72
A21: Grade cost table (SAR '000 per annum) | F21: Illustrative rates — replace with Finance's own before use.
A22: Grade | B22: Basic | C22: Housing | D22: Transport | E22: Bonus % | F22: Rank
A23: G9 | B23: 96 | C23: 24 | D23: 12 | E23: 0.05 | F23: 1
A24: G10 | B24: 120 | C24: 30 | D24: 12 | E24: 0.06 | F24: 2
A25: G11 | B25: 150 | C25: 38 | D25: 14 | E25: 0.08 | F25: 3
A26: G12 | B26: 192 | C26: 48 | D26: 14 | E26: 0.1 | F26: 4
A27: G13 | B27: 252 | C27: 63 | D27: 18 | E27: 0.12 | F27: 5
